Navigating to the scheduling page...
On scheduling page.
Booking first appointment...
An error occurred during the test:
Traceback (most recent call last):
  File "/app/jules-scratch/verification/verify_coupon_feature.py", line 12, in test_coupon_feature
    page.locator('[data-testid="date-grid"] button').first.click()
  File "/home/jules/.pyenv/versions/3.12.11/lib/python3.12/site-packages/playwright/sync_api/_generated.py", line 15524, in click
    self._sync(
  File "/home/jules/.pyenv/versions/3.12.11/lib/python3.12/site-packages/playwright/_impl/_sync_base.py", line 115, in _sync
    return task.result()
           ^^^^^^^^^^^^^
  File "/home/jules/.pyenv/versions/3.12.11/lib/python3.12/site-packages/playwright/_impl/_locator.py", line 160, in click
    return await self._frame.click(self._selector, strict=True, **params)
           ^^^^^^^^^^^^^^^^^^^^^^^^^^^^^^^^^^^^^^^^^^^^^^^^^^^^^^^^^^^^^^
  File "/home/jules/.pyenv/versions/3.12.11/lib/python3.12/site-packages/playwright/_impl/_frame.py", line 549, in click
    await self._channel.send("click", self._timeout, locals_to_params(locals()))
  File "/home/jules/.pyenv/versions/3.12.11/lib/python3.12/site-packages/playwright/_impl/_connection.py", line 69, in send
    return await self._connection.wrap_api_call(
           ^^^^^^^^^^^^^^^^^^^^^^^^^^^^^^^^^^^^^
  File "/home/jules/.pyenv/versions/3.12.11/lib/python3.12/site-packages/playwright/_impl/_connection.py", line 558, in wrap_api_call
    raise rewrite_error(error, f"{parsed_st['apiName']}: {error}") from None
playwright._impl._errors.TimeoutError: Locator.click: Timeout 30000ms exceeded.
Call log:
  - waiting for locator("[data-testid=\"date-grid\"] button").first
